Workbook

Sheet Price List
A1: PRODUCT PRICE LIST
A2: All prices in INR. 500 g = half of 1 Kg rate, 250 g = one-fourth — each rounded so the last two digits are 99.
A4: S. No. | B4: Product | C4: Price per 1 Kg (₹) | D4: Price per 500 g (₹) | E4: Price per 250 g (₹)
A5: Cashew (Kaju)
A6: 1 | B6: Kaju 320 N | C6: ='All Products (Filterable)'!D2 -> 1899 | D6: ='All Products (Filterable)'!E2 -> 999 | E6: ='All Products (Filterable)'!F2 -> 499
A7: 2 | B7: Kaju 240 N | C7: ='All Products (Filterable)'!D3 -> 2199 | D7: ='All Products (Filterable)'!E3 -> 1099 | E7: ='All Products (Filterable)'!F3 -> 599
A8: 3 | B8: Kaju 210 N | C8: ='All Products (Filterable)'!D4 -> 2499 | D8: ='All Products (Filterable)'!E4 -> 1299 | E8: ='All Products (Filterable)'!F4 -> 699
A9: 4 | B9: Kaju 180 N | C9: ='All Products (Filterable)'!D5 -> 2699 | D9: ='All Products (Filterable)'!E5 -> 1399 | E9: ='All Products (Filterable)'!F5 -> 699
A10: 5 | B10: Kaju Roasted | C10: ='All Products (Filterable)'!D6 -> 2199 | D10: ='All Products (Filterable)'!E6 -> 1099 | E10: ='All Products (Filterable)'!F6 -> 599
A11: 6 | B11: Kaju Fry Salted | C11: ='All Products (Filterable)'!D7 -> 2199 | D11: ='All Products (Filterable)'!E7 -> 1099 | E11: ='All Products (Filterable)'!F7 -> 599
A12: 7 | B12: Kaju Masala | C12: ='All Products (Filterable)'!D8 -> 2199 | D12: ='All Products (Filterable)'!E8 -> 1099 | E12: ='All Products (Filterable)'!F8 -> 599
A13: Almonds (Badam)
A14: 8 | B14: Badam CF | C14: ='All Products (Filterable)'!D9 -> 1599 | D14: ='All Products (Filterable)'!E9 -> 799 | E14: ='All Products (Filterable)'!F9 -> 399
A15: 9 | B15: Badam AS | C15: ='All Products (Filterable)'!D10 -> 2499 | D15: ='All Products (Filterable)'!E10 -> 1299 | E15: ='All Products (Filterable)'!F10 -> 699
A16: 10 | B16: Badam Roasted | C16: ='All Products (Filterable)'!D11 -> 2199 | D16: ='All Products (Filterable)'!E11 -> 1099 | E16: ='All Products (Filterable)'!F11 -> 599
A17: Mamra Almonds (Irani)
A18: 11 | B18: Irani Mamra Small | C18: ='All Products (Filterable)'!D12 -> 5999 | D18: ='All Products (Filterable)'!E12 -> 2999 | E18: ='All Products (Filterable)'!F12 -> 1499
A19: 12 | B19: Irani Mamra Medium | C19: ='All Products (Filterable)'!D13 -> 6599 | D19: ='All Products (Filterable)'!E13 -> 3299 | E19: ='All Products (Filterable)'!F13 -> 1699
A20: 13 | B20: Irani Mamra Jumbo | C20: ='All Products (Filterable)'!D14 -> 7999 | D20: ='All Products (Filterable)'!E14 -> 3999 | E20: ='All Products (Filterable)'!F14 -> 1999
A21: Pistachio (Pista)
A22: 14 | B22: Pista | C22: ='All Products (Filterable)'!D15 -> 2199 | D22: ='All Products (Filterable)'!E15 -> 1099 | E22: ='All Products (Filterable)'!F15 -> 599
A23: 15 | B23: Pista Irani | C23: ='All Products (Filterable)'!D16 -> 2499 | D23: ='All Products (Filterable)'!E16 -> 1299 | E23: ='All Products (Filterable)'!F16 -> 699
A24: 16 | B24: Green Pista | C24: ='All Products (Filterable)'!D17 -> 4299 | D24: ='All Products (Filterable)'!E17 -> 2199 | E24: ='All Products (Filterable)'!F17 -> 1099
A25: 17 | B25: Pista Green Barik | C25: ='All Products (Filterable)'!D18 -> 4899 | D25: ='All Products (Filterable)'!E18 -> 2499 | E25: ='All Products (Filterable)'!F18 -> 1299
A26: Raisins (Kishmish & Munakka)
A27: 18 | B27: Kishmish Indian | C27: ='All Products (Filterable)'!D19 -> 1199 | D27: ='All Products (Filterable)'!E19 -> 599 | E27: ='All Products (Filterable)'!F19 -> 299
A28: 19 | B28: Kishmish Kandhari | C28: ='All Products (Filterable)'!D20 -> 2699 | D28: ='All Products (Filterable)'!E20 -> 1399 | E28: ='All Products (Filterable)'!F20 -> 699
A29: 20 | B29: Kishmish Indian Long | C29: ='All Products (Filterable)'!D21 -> 1599 | D29: ='All Products (Filterable)'!E21 -> 799 | E29: ='All Products (Filterable)'!F21 -> 399
A30: 21 | B30: Black Kishmish | C30: ='All Products (Filterable)'!D22 -> 1399 | D30: ='All Products (Filterable)'!E22 -> 699 | E30: ='All Products (Filterable)'!F22 -> 399
A31: 22 | B31: Munakka Basic | C31: ='All Products (Filterable)'!D23 -> 1599 | D31: ='All Products (Filterable)'!E23 -> 799 | E31: ='All Products (Filterable)'!F23 -> 399
A32: 23 | B32: Munakka Premium | C32: ='All Products (Filterable)'!D24 -> 2499 | D32: ='All Products (Filterable)'!E24 -> 1299 | E32: ='All Products (Filterable)'!F24 -> 699
A33: Figs (Anjeer)
A34: 24 | B34: Anjeer Small | C34: ='All Products (Filterable)'!D25 -> 2699 | D34: ='All Products (Filterable)'!E25 -> 1399 | E34: ='All Products (Filterable)'!F25 -> 699
A35: 25 | B35: Anjeer Medium | C35: ='All Products (Filterable)'!D26 -> 3199 | D35: ='All Products (Filterable)'!E26 -> 1599 | E35: ='All Products (Filterable)'!F26 -> 799
A36: 26 | B36: Anjeer Jumbo | C36: ='All Products (Filterable)'!D27 -> 4599 | D36: ='All Products (Filterable)'!E27 -> 2299 | E36: ='All Products (Filterable)'!F27 -> 1199
A37: Walnuts (Akhrot)
A38: 27 | B38: Walnut Basic | C38: ='All Products (Filterable)'!D28 -> 2499 | D38: ='All Products (Filterable)'!E28 -> 1299 | E38: ='All Products (Filterable)'!F28 -> 699
A39: 28 | B39: Walnut Premium | C39: ='All Products (Filterable)'!D29 -> 3999 | D39: ='All Products (Filterable)'!E29 -> 1999 | E39: ='All Products (Filterable)'!F29 -> 999
A40: 29 | B40: Walnut In Shell | C40: ='All Products (Filterable)'!D30 -> 1899 | D40: ='All Products (Filterable)'!E30 -> 999 | E40: ='All Products (Filterable)'!F30 -> 499
A41: Pine Nuts (Chilgoza)
...

Sheet Sheet

Sheet All Products (Filterable)
A1: Category | B1: Product | C1: Printed Price (₹/Kg) | D1: Price per 1 Kg (₹) | E1: Price per 500 g (₹) | F1: Price per 250 g (₹)
A2: Cashew (Kaju) | B2: Kaju 320 N | C2: 1899 | D2: =INT($C2/100)*100+99 -> 1899 | E2: =INT($C2/2/100)*100+99 -> 999 | F2: =INT($C2/4/100)*100+99 -> 499
A3: Cashew (Kaju) | B3: Kaju 240 N | C3: 2199 | D3: =INT($C3/100)*100+99 -> 2199 | E3: =INT($C3/2/100)*100+99 -> 1099 | F3: =INT($C3/4/100)*100+99 -> 599
A4: Cashew (Kaju) | B4: Kaju 210 N | C4: 2499 | D4: =INT($C4/100)*100+99 -> 2499 | E4: =INT($C4/2/100)*100+99 -> 1299 | F4: =INT($C4/4/100)*100+99 -> 699
A5: Cashew (Kaju) | B5: Kaju 180 N | C5: 2699 | D5: =INT($C5/100)*100+99 -> 2699 | E5: =INT($C5/2/100)*100+99 -> 1399 | F5: =INT($C5/4/100)*100+99 -> 699
A6: Cashew (Kaju) | B6: Kaju Roasted | C6: 2199 | D6: =INT($C6/100)*100+99 -> 2199 | E6: =INT($C6/2/100)*100+99 -> 1099 | F6: =INT($C6/4/100)*100+99 -> 599
A7: Cashew (Kaju) | B7: Kaju Fry Salted | C7: 2199 | D7: =INT($C7/100)*100+99 -> 2199 | E7: =INT($C7/2/100)*100+99 -> 1099 | F7: =INT($C7/4/100)*100+99 -> 599
A8: Cashew (Kaju) | B8: Kaju Masala | C8: 2199 | D8: =INT($C8/100)*100+99 -> 2199 | E8: =INT($C8/2/100)*100+99 -> 1099 | F8: =INT($C8/4/100)*100+99 -> 599
A9: Almonds (Badam) | B9: Badam CF | C9: 1599 | D9: =INT($C9/100)*100+99 -> 1599 | E9: =INT($C9/2/100)*100+99 -> 799 | F9: =INT($C9/4/100)*100+99 -> 399
A10: Almonds (Badam) | B10: Badam AS | C10: 2499 | D10: =INT($C10/100)*100+99 -> 2499 | E10: =INT($C10/2/100)*100+99 -> 1299 | F10: =INT($C10/4/100)*100+99 -> 699
A11: Almonds (Badam) | B11: Badam Roasted | C11: 2199 | D11: =INT($C11/100)*100+99 -> 2199 | E11: =INT($C11/2/100)*100+99 -> 1099 | F11: =INT($C11/4/100)*100+99 -> 599
A12: Mamra Almonds (Irani) | B12: Irani Mamra Small | C12: 5999 | D12: =INT($C12/100)*100+99 -> 5999 | E12: =INT($C12/2/100)*100+99 -> 2999 | F12: =INT($C12/4/100)*100+99 -> 1499
A13: Mamra Almonds (Irani) | B13: Irani Mamra Medium | C13: 6599 | D13: =INT($C13/100)*100+99 -> 6599 | E13: =INT($C13/2/100)*100+99 -> 3299 | F13: =INT($C13/4/100)*100+99 -> 1699
... A86: Mouth Fresheners | B86: Mango Candy | C86: 1199 | D86: =INT($C86/100)*100+99 -> 1199 | E86: =INT($C86/2/100)*100+99 -> 599 | F86: =INT($C86/4/100)*100+99 -> 299
A88: Blue figures = printed supplier rate (source: supplier price sheet photos). All other prices are formulas: value rounded so the last two digits are 99 (500 g = half of 1 Kg, 250 g = one-fourth of 1 Kg).

Sheet Category Summary
A1: Category | B1: No. of Products | C1: Lowest 1 Kg Rate (₹) | D1: Highest 1 Kg Rate (₹) | E1: Average 1 Kg Rate (₹)
A2: Cashew (Kaju) | B2: =COUNTIF('All Products (Filterable)'!$A$2:$A$86,$A2) -> 7 | C2: =_xlfn.MINIFS('All Products (Filterable)'!$D$2:$D$86,'All Products (Filterable)'!$A$2:$A$86,$A2) -> 1899 | D2: =_xlfn.MAXIFS('All Products (Filterable)'!$D$2:$D$86,'All Products (Filterable)'!$A$2:$A$86,$A2) -> 2699 | E2: =SUMIF('All Products (Filterable)'!$A$2:$A$86,$A2,'All Products (Filterable)'!$D$2:$D$86)/$B2 -> 2270.4286
A3: Almonds (Badam) | B3: =COUNTIF('All Products (Filterable)'!$A$2:$A$86,$A3) -> 3 | C3: =_xlfn.MINIFS('All Products (Filterable)'!$D$2:$D$86,'All Products (Filterable)'!$A$2:$A$86,$A3) -> 1599 | D3: =_xlfn.MAXIFS('All Products (Filterable)'!$D$2:$D$86,'All Products (Filterable)'!$A$2:$A$86,$A3) -> 2499 | E3: =SUMIF('All Products (Filterable)'!$A$2:$A$86,$A3,'All Products (Filterable)'!$D$2:$D$86)/$B3 -> 2099
A4: Mamra Almonds (Irani) | B4: =COUNTIF('All Products (Filterable)'!$A$2:$A$86,$A4) -> 3 | C4: =_xlfn.MINIFS('All Products (Filterable)'!$D$2:$D$86,'All Products (Filterable)'!$A$2:$A$86,$A4) -> 5999 | D4: =_xlfn.MAXIFS('All Products (Filterable)'!$D$2:$D$86,'All Products (Filterable)'!$A$2:$A$86,$A4) -> 7999 | E4: =SUMIF('All Products (Filterable)'!$A$2:$A$86,$A4,'All Products (Filterable)'!$D$2:$D$86)/$B4 -> 6865.6667
A5: Pistachio (Pista) | B5: =COUNTIF('All Products (Filterable)'!$A$2:$A$86,$A5) -> 4 | C5: =_xlfn.MINIFS('All Products (Filterable)'!$D$2:$D$86,'All Products (Filterable)'!$A$2:$A$86,$A5) -> 2199 | D5: =_xlfn.MAXIFS('All Products (Filterable)'!$D$2:$D$86,'All Products (Filterable)'!$A$2:$A$86,$A5) -> 4899 | E5: =SUMIF('All Products (Filterable)'!$A$2:$A$86,$A5,'All Products (Filterable)'!$D$2:$D$86)/$B5 -> 3474
A6: Raisins (Kishmish & Munakka) | B6: =COUNTIF('All Products (Filterable)'!$A$2:$A$86,$A6) -> 6 | C6: =_xlfn.MINIFS('All Products (Filterable)'!$D$2:$D$86,'All Products (Filterable)'!$A$2:$A$86,$A6) -> 1199 | D6: =_xlfn.MAXIFS('All Products (Filterable)'!$D$2:$D$86,'All Products (Filterable)'!$A$2:$A$86,$A6) -> 2699 | E6: =SUMIF('All Products (Filterable)'!$A$2:$A$86,$A6,'All Products (Filterable)'!$D$2:$D$86)/$B6 -> 1832.3333
A7: Figs (Anjeer) | B7: =COUNTIF('All Products (Filterable)'!$A$2:$A$86,$A7) -> 3 | C7: =_xlfn.MINIFS('All Products (Filterable)'!$D$2:$D$86,'All Products (Filterable)'!$A$2:$A$86,$A7) -> 2699 | D7: =_xlfn.MAXIFS('All Products (Filterable)'!$D$2:$D$86,'All Products (Filterable)'!$A$2:$A$86,$A7) -> 4599 | E7: =SUMIF('All Products (Filterable)'!$A$2:$A$86,$A7,'All Products (Filterable)'!$D$2:$D$86)/$B7 -> 3499
A8: Walnuts (Akhrot) | B8: =COUNTIF('All Products (Filterable)'!$A$2:$A$86,$A8) -> 3 | C8: =_xlfn.MINIFS('All Products (Filterable)'!$D$2:$D$86,'All Products (Filterable)'!$A$2:$A$86,$A8) -> 1899 | D8: =_xlfn.MAXIFS('All Products (Filterable)'!$D$2:$D$86,'All Products (Filterable)'!$A$2:$A$86,$A8) -> 3999 | E8: =SUMIF('All Products (Filterable)'!$A$2:$A$86,$A8,'All Products (Filterable)'!$D$2:$D$86)/$B8 -> 2799
A9: Pine Nuts (Chilgoza) | B9: =COUNTIF('All Products (Filterable)'!$A$2:$A$86,$A9) -> 2 | C9: =_xlfn.MINIFS('All Products (Filterable)'!$D$2:$D$86,'All Products (Filterable)'!$A$2:$A$86,$A9) -> 8499 | D9: =_xlfn.MAXIFS('All Products (Filterable)'!$D$2:$D$86,'All Products (Filterable)'!$A$2:$A$86,$A9) -> 10599 | E9: =SUMIF('All Products (Filterable)'!$A$2:$A$86,$A9,'All Products (Filterable)'!$D$2:$D$86)/$B9 -> 9549
A10: Exotic & Mixed Nuts | B10: =COUNTIF('All Products (Filterable)'!$A$2:$A$86,$A10) -> 5 | C10: =_xlfn.MINIFS('All Products (Filterable)'!$D$2:$D$86,'All Products (Filterable)'!$A$2:$A$86,$A10) -> 2199 | D10: =_xlfn.MAXIFS('All Products (Filterable)'!$D$2:$D$86,'All Products (Filterable)'!$A$2:$A$86,$A10) -> 5999 | E10: =SUMIF('All Products (Filterable)'!$A$2:$A$86,$A10,'All Products (Filterable)'!$D$2:$D$86)/$B10 -> 4279
A11: Makhana | B11: =COUNTIF('All Products (Filterable)'!$A$2:$A$86,$A11) -> 1 | C11: =_xlfn.MINIFS('All Products (Filterable)'!$D$2:$D$86,'All Products (Filterable)'!$A$2:$A$86,$A11) -> 2199 | D11: =_xlfn.MAXIFS('All Products (Filterable)'!$D$2:$D$86,'All Products (Filterable)'!$A$2:$A$86,$A11) -> 2199 | E11: =SUMIF('All Products (Filterable)'!$A$2:$A$86,$A11,'All Products (Filterable)'!$D$2:$D$86)/$B11 -> 2199
A12: Dates & Apricot | B12: =COUNTIF('All Products (Filterable)'!$A$2:$A$86,$A12) -> 2 | C12: =_xlfn.MINIFS('All Products (Filterable)'!$D$2:$D$86,'All Products (Filterable)'!$A$2:$A$86,$A12) -> 1899 | D12: =_xlfn.MAXIFS('All Products (Filterable)'!$D$2:$D$86,'All Products (Filterable)'!$A$2:$A$86,$A12) -> 2799 | E12: =SUMIF('All Products (Filterable)'!$A$2:$A$86,$A12,'All Products (Filterable)'!$D$2:$D$86)/$B12 -> 2349
A13: Seeds | B13: =COUNTIF('All Products (Filterable)'!$A$2:$A$86,$A13) -> 10 | C13: =_xlfn.MINIFS('All Products (Filterable)'!$D$2:$D$86,'All Products (Filterable)'!$A$2:$A$86,$A13) -> 799 | D13: =_xlfn.MAXIFS('All Products (Filterable)'!$D$2:$D$86,'All Products (Filterable)'!$A$2:$A$86,$A13) -> 3699 | E13: =SUMIF('All Products (Filterable)'!$A$2:$A$86,$A13,'All Products (Filterable)'!$D$2:$D$86)/$B13 -> 1509
... A21: Mouth Fresheners | B21: =COUNTIF('All Products (Filterable)'!$A$2:$A$86,$A21) -> 3 | C21: =_xlfn.MINIFS('All Products (Filterable)'!$D$2:$D$86,'All Products (Filterable)'!$A$2:$A$86,$A21) -> 1199 | D21: =_xlfn.MAXIFS('All Products (Filterable)'!$D$2:$D$86,'All Products (Filterable)'!$A$2:$A$86,$A21) -> 1299 | E21: =SUMIF('All Products (Filterable)'!$A$2:$A$86,$A21,'All Products (Filterable)'!$D$2:$D$86)/$B21 -> 1265.6667
A22: TOTAL | B22: =SUM(B2:B21) -> 85
